<?xml version="1.0"?>
<robot xmlns:xacro="http://ros.org/wiki/xacro" name="robot_name2">
    
    <link name="robot2_base_footprint">
        <origin xyz="0.0 0.0 0.0" rpy="0.0 0.0 0.0"/>
    </link>

    <link name="robot2_base_link">
        <inertial>
            <mass value="2.0"/>
            <origin xyz="0.0 0.0 0.0" rpy="0.0 0.0 0.0"/>
            <inertia ixx="0.05" ixy="0.0" ixz="0.0" iyy="0.05" iyz="0.0" izz="0.1"/>
        </inertial>
        <visual>
            <origin xyz="0.0 0.0 0.0" rpy="0.0 0.0 0.0"/>
            <geometry>
                <mesh filename="file:///home/kareem/ros2_ws/src/my_robot_description/meshes/f_body.stl" scale="1.0 1.0 1.0"/>
            </geometry>
        </visual>
        <collision>
            <origin xyz="0.0 0.0 0.0" rpy="0.0 0.0 0.0"/>
            <geometry>
                <mesh filename="file:///home/kareem/ros2_ws/src/my_robot_description/meshes/f_body.stl" scale="1.0 1.0 1.0"/>
            </geometry>
        </collision>
    </link>

    <joint name="robot2_base_joint" type="fixed">
        <origin xyz="0.0 0.0 0.069887" rpy="0.0 0.0 0.0"/>
        <parent link="robot2_base_footprint"/>
        <child link="robot2_base_link"/>
    </joint>

    <link name="robot2_right_wheel_link">
        <inertial>
            <origin xyz="0 0.0 0" rpy="0 0 0" />
            <mass value="0.0530086043217644" />
            <inertia ixx="1.8792911368909E-05" ixy="3.31256392204584E-10" ixz="-1.14082001662767E-08" iyy="3.11510738759073E-05" iyz="-3.60499245082192E-10" izz="1.88266886146847E-05" />
        </inertial>
        <visual>
            <origin xyz="0 0 0 " rpy="0.0 0.0 0.0"/>
            <geometry>
                <mesh filename="file:///home/kareem/ros2_ws/src/my_robot_description/meshes/f_r_wheel.stl" scale="1.0 1.0 1.0"/>
            </geometry>
        </visual>
        <collision>
            <origin xyz="0.0 0.0 0.0" rpy="0.0 0.0 0.0"/>
            <geometry>
                <mesh filename="file:///home/kareem/ros2_ws/src/my_robot_description/meshes/f_r_wheel.stl" scale="1.0 1.0 1.0"/>
            </geometry>
        </collision>
    </link>

    <joint name="robot2_right_wheel_joint" type="continuous">
        <parent link="robot2_base_link"/>
        <child link="robot2_right_wheel_link"/>
        <axis xyz="0 1 0"/>
        <origin xyz="-0.004419 -0.144966 -0.032927" rpy="0 0 0"/>
    </joint>

    <link name="robot2_left_wheel_link">
        <inertial>
            <origin xyz="0 0.0 0" rpy="0 0 0" />
            <mass value="0.0530086043217644" />
            <inertia ixx="1.8792911368909E-05" ixy="3.31256392204584E-10" ixz="-1.14082001662767E-08" iyy="3.11510738759073E-05" iyz="-3.60499245082192E-10" izz="1.88266886146847E-05" />
        </inertial>
        <visual>
            <origin xyz="0 0 0" rpy="0.0 0.0 0.0"/>
            <geometry>
                <mesh filename="file:///home/kareem/ros2_ws/src/my_robot_description/meshes/f_l_wheel.stl" scale="1.0 1.0 1.0"/>
            </geometry>
        </visual>
        <collision>
            <origin xyz="0.0 0.0 0.0" rpy="0.0 0.0 0.0"/>
            <geometry>
                <mesh filename="file:///home/kareem/ros2_ws/src/my_robot_description/meshes/f_l_wheel.stl" scale="1.0 1.0 1.0"/>
            </geometry>
        </collision>
    </link>

    <joint name="robot2_left_wheel_joint" type="continuous">
        <parent link="robot2_base_link"/>
        <child link="robot2_left_wheel_link"/>
        <axis xyz="0 1 0"/>
        <origin xyz="0.004419 0.144966 -0.032927" rpy="0 0 0"/>
    </joint>

    <link name="robot2_caster_front_wheel_link">
        <inertial>
            <origin xyz="0.1 0 -0.049389" rpy="0 0 0" />
            <mass value="1.44379265037902E-06" />
            <inertia ixx="7.23075276010246E-11" ixy="-6.10956872363424E-16" ixz="2.22849693527207E-15"
                     iyy="3.87137930859167E-11" iyz="2.939098587861E-15"
                     izz="1.00967486676306E-10" />
        </inertial>
        <origin xyz="0.0 0 0.0" rpy="0 0 0" />
        <visual>
            <geometry>
                <mesh filename="file:///home/kareem/ros2_ws/src/my_robot_description/meshes/f_caster.stl" scale="1.0 1.0 1.0"/>
            </geometry>
        </visual>
        <collision>
            <origin xyz="0.0 0.0 0.0" rpy="0.0 0.0 0.0"/>
            <geometry>
                <mesh filename="file:///home/kareem/ros2_ws/src/my_robot_description/meshes/f_caster.stl" scale="1.0 1.0 1.0"/>
            </geometry>
        </collision>
    </link>

    <joint name="robot2_base_fcaster_wheel_joint" type="fixed">
        <parent link="robot2_base_link" />
        <child link="robot2_caster_front_wheel_link" />
        <origin xyz="0.1 0 -0.049389" rpy="0 0 0" />
    </joint>

    <link name="robot2_caster_rear_wheel_link">
        <origin xyz="0.0 0 0.0" rpy="0 0 0" />
        <inertial>
            <origin xyz="-0.121592 0 -0.049389" rpy="0 0 0" />
            <mass value="1.44379265037902E-06" />
            <inertia ixx="7.23075276010246E-11" ixy="-6.10956872363424E-16" ixz="2.22849693527207E-15"
                     iyy="3.87137930859167E-11" iyz="2.939098587861E-15"
                     izz="1.00967486676306E-10" />
        </inertial>
        <visual>
            <geometry>
                <mesh filename="file:///home/kareem/ros2_ws/src/my_robot_description/meshes/r_caster.stl" scale="1.0 1.0 1.0"/>
            </geometry>
        </visual>
        <collision>
            <origin xyz="0.0 0.0 0.0" rpy="0.0 0.0 0.0"/>
            <geometry>
                <mesh filename="file:///home/kareem/ros2_ws/src/my_robot_description/meshes/r_caster.stl" scale="1.0 1.0 1.0"/>
            </geometry>
        </collision>
    </link>

    <joint name="robot2_base_rcaster_wheel_joint" type="fixed">
        <parent link="robot2_base_link" />
        <child link="robot2_caster_rear_wheel_link" />
        <origin xyz="-0.121592 0 -0.049389" rpy="0 0 0" />
    </joint>

    <link name="robot2_imu_link">
        <origin xyz="0.0 0 0.12" rpy="0 0 0" />
        <visual>
            <geometry>
                <box size="0.01 0.01 0.01"/>
            </geometry>
            <collision>
                <geometry>
                    <box size="0.01 0.01 0.01"/>
                </geometry>
            </collision>
        </visual>
        <inertial>
            <origin xyz="0.0 0 0.12" rpy="0 0 0" />
            <mass value="0.001" />
            <inertia ixx="7.23075276010246E-11" ixy="-6.10956872363424E-16" ixz="2.22849693527207E-15"
                     iyy="3.87137930859167E-11" iyz="2.939098587861E-15"
                     izz="1.00967486676306E-10" />
        </inertial>
    </link>

    <joint name="robot2_base_imu_joint" type="fixed">
        <parent link="robot2_base_link" />
        <child link="robot2_imu_link" />
        <origin xyz="0 0 0" rpy="0 0 0" />
    </joint>

    <link name="robot2_lidar_link">
        <origin xyz="0.2 0 0.0" rpy="0 0 0" />
        <visual>
            <geometry>
                <cylinder radius="0.001" length="0.001"/>
            </geometry>
            <collision>
                <geometry>
                    <cylinder radius="0.001" length="0.001"/>
                </geometry>
            </collision>
        </visual>
        <inertial>
            <origin xyz="0.2 0 0.2" rpy="0 0 0" />
            <mass value="0.001" />
            <inertia ixx="7.23075276010246E-11" ixy="-6.10956872363424E-16" ixz="2.22849693527207E-15"
                     iyy="3.87137930859167E-11" iyz="2.939098587861E-15"
                     izz="1.00967486676306E-10" />
        </inertial>
    </link>

    <joint name="robot2_base_lidar_joint" type="fixed">
        <parent link="robot2_base_link" />
        <child link="robot2_lidar_link" />
        <origin xyz="0.15 0 0.15" rpy="0 0 0" />
    </joint>

    <gazebo reference="robot2_right_wheel_link">
        <mu1>100000000000000.0</mu1>
        <mu2>100000000000000.0</mu2>
        <kp>1000000000000.0</kp>
        <kd>1000000000000.0</kd>
        <minDepth>0.001</minDepth>
        <maxVel>0.1</maxVel>
        <fdirl>0 1 0</fdirl>
    </gazebo>

    <gazebo reference="robot2_left_wheel_link">
        <mu1>100000000000000.0</mu1>
        <mu2>100000000000000.0</mu2>
        <kp>1000000000000.0</kp>
        <kd>1000000000000.0</kd>
        <minDepth>0.001</minDepth>
        <maxVel>0.1</maxVel>
        <fdirl>0 1 0</fdirl>
    </gazebo>

    <gazebo reference="robot2_caster_rear_wheel_link">
        <mu1>0.1</mu1>
        <mu2>0.1</mu2>
        <kp>1000000.0</kp>
        <kd>100.0</kd>
        <minDepth>0.001</minDepth>
        <maxVel>1.0</maxVel>
    </gazebo>

    <gazebo reference="robot2_caster_front_wheel_link">
        <mu1>0.1</mu1>
        <mu2>0.1</mu2>
        <kp>1000000.0</kp>
        <kd>100.0</kd>
        <minDepth>0.001</minDepth>
        <maxVel>1.0</maxVel>
    </gazebo>

    <gazebo reference="robot2_imu_link">
        <sensor name="robot2_imu_sensor" type="imu">
            <plugin filename="libgazebo_ros_imu_sensor.so" name="imu_plugin">
                <ros>
                    <topicName>robot2_imu_data</topicName>
                    <remapping>~/out:=imu2</remapping>
                </ros>
                <initial_orientation_as_reference>false</initial_orientation_as_reference>
            </plugin>
            <always_on>true</always_on>
            <update_rate>100</update_rate>
            <visualize>true</visualize>
            <imu>
                <angular_velocity>
                    <x>
                        <noise type="gaussian">
                            <mean>0.0</mean>
                            <stddev>2e-4</stddev>
                            <bias_mean>0.0000075</bias_mean>
                            <bias_stddev>0.0000008</bias_stddev>
                        </noise>
                    </x>
                    <y>
                        <noise type="gaussian">
                            <mean>0.0</mean>
                            <stddev>2e-4</stddev>
                            <bias_mean>0.0000075</bias_mean>
                            <bias_stddev>0.0000008</bias_stddev>
                        </noise>
                    </y>
                    <z>
                        <noise type="gaussian">
                            <mean>0.0</mean>
                            <stddev>2e-4</stddev>
                            <bias_mean>0.0000075</bias_mean>
                            <bias_stddev>0.0000008</bias_stddev>
                        </noise>
                    </z>
                </angular_velocity>
                <linear_acceleration>
                    <x>
                        <noise type="gaussian">
                            <mean>0.0</mean>
                            <stddev>1.7e-2</stddev>
                            <bias_mean>0.1</bias_mean>
                            <bias_stddev>0.001</bias_stddev>
                        </noise>
                    </x>
                    <y>
                        <noise type="gaussian">
                            <mean>0.0</mean>
                            <stddev>1.7e-2</stddev>
                            <bias_mean>0.1</bias_mean>
                            <bias_stddev>0.001</bias_stddev>
                        </noise>
                    </y>
                    <z>
                        <noise type="gaussian">
                            <mean>0.0</mean>
                            <stddev>1.7e-2</stddev>
                            <bias_mean>0.1</bias_mean>
                            <bias_stddev>0.001</bias_stddev>
                        </noise>
                    </z>
                </linear_acceleration>
            </imu>
        </sensor>
    </gazebo>

    <gazebo>
        <plugin name='diff_drive' filename='libgazebo_ros_diff_drive.so'>
    
          <left_joint>robot2_left_wheel_joint</left_joint>
          <right_joint>robot2_right_wheel_joint</right_joint>
    
          <wheel_separation>0.289932</wheel_separation>
          <wheel_diameter>0.065</wheel_diameter>
    
          <!-- Adjust limits as per your robot's capabilities -->
          <max_wheel_torque>200</max_wheel_torque> <!-- Maximum torque applied to the wheels -->
          <max_wheel_accel>10.0</max_wheel_accel> <!-- Maximum acceleration of the wheels -->
    
          <!-- Choose whether to publish odometry, odom TF, and wheel TF -->
          <publish_odom>true</publish_odom> <!-- Whether to publish odometry -->
          <publish_odom_tf>true</publish_odom_tf> <!-- Whether to publish odometry TF -->
          <publish_wheel_tf>true</publish_wheel_tf> <!-- Whether to publish wheel TF -->
    
          <!-- Update frame names according to your robot's URDF -->
          <odometry_frame>odom</odometry_frame> <!-- Frame for odometry data -->
          <robot_base_frame>robot2_base_footprint</robot_base_frame> <!-- Base frame of the robot -->
        </plugin>
      </gazebo>
    

    <gazebo reference="robot2_lidar_link">
      <sensor name="gazebo_lidar" type="ray">
        <pose>0 0 0 0 0 0</pose>
        <always_on>true</always_on>
        <visualize>true</visualize>
        <update_rate>10.0</update_rate>
        <plugin filename="libgazebo_ros_ray_sensor.so" name="gazebo_lidar">
            <ros>
              <remapping>~/out:=scan2</remapping>
            </ros>
            <output_type>sensor_msgs/LaserScan</output_type>
            <frame_name>robot2_lidar_link</frame_name>
        </plugin>
        <ray>
          <scan>
            <horizontal>
              <samples>360</samples>
              <resolution>1</resolution>
              <min_angle>-3.14</min_angle>
              <max_angle>3.14</max_angle>
            </horizontal>
          </scan>
          <range>
            <min>0.120</min>
            <max>3.5</max>
            <resolution>0.015</resolution>
          </range>
          <noise>
            <type>gaussian</type>
            <mean>0.0</mean>
            <stddev>0.01</stddev>
          </noise>
        </ray>
      </sensor>
   </gazebo>
    
</robot>
